using System;

/**
 * InnerException: хранит информацию об исключении, которое послужило причиной текущего исключения
 * Message: хранит сообщение об исключении, текст ошибки
 * Source: хранит имя объекта или сборки, которое вызвало исключение
 * StackTrace: возвращает строковое представление стека вызывов, которые привели к возникновению исключения
 * TargetSite: возвращает метод, в котором и было вызвано исключение
 */

namespace _3.Типы_исключений.Класс_Exception
{
    class Program
    {
        static void Main(string[] args)
        {
            try
            {
                int x = 5;
                int y = x / 0;
                Console.WriteLine($"Результат: {y}");
            }
            catch (Exception ex)
            {
                Console.WriteLine($"Исключение: {ex.Message}");
                Console.WriteLine($"Метод: {ex.TargetSite}");
                Console.WriteLine($"Трассировка стека: {ex.StackTrace}");
            }

            try
            {
                int[] numbers = new int[4];
                numbers[7] = 9;     // IndexOutOfRangeException

                int x = 5;
                int y = x / 0;  // DivideByZeroException
                Console.WriteLine($"Результат: {y}");
            }
            catch (DivideByZeroException)
            {
                Console.WriteLine("Возникло исключение DivideByZeroException");
            }
            catch (IndexOutOfRangeException ex)
            {
                Console.WriteLine(ex.Message);
            }

            try
            {
                object obj = "you";
                int num = (int)obj;     // InvalidCastException
                Console.WriteLine($"Результат: {num}");
            }
            catch (DivideByZeroException)
            {
                Console.WriteLine("Возникло исключение DivideByZeroException");
            }
            catch (IndexOutOfRangeException)
            {
                Console.WriteLine("Возникло исключение IndexOutOfRangeException");
            }
            catch (Exception ex)
            {
                Console.WriteLine($"Исключение: {ex.Message}");
            }

            Console.ReadKey();
        }
    }
}
